Workbook

Sheet Check Value
A1: AVALREM - ACTION VALUE CALCULATOR
B3: Kirdomic Avalrem System Interface
B4: Intrinsic Value of Action Word
B6: Please Enter an Action Word here ---> | K6: ='Primary Value'!E45 -> Eliminate
C8: Intrinsic 'C' Value: ------> | K8: =SUMIF('Master Data'!AI141:AI292,'Check Value'!K6,'Master Data'!G141:G292) -> 12.652616
B10: Extended Criteria for Intrinsic Value Check
B12: Please Enter Criteria Below:
B14: * | C14: Kirdomic Card Number (enter card number 1 to 12) | K14: 6
B16: * | C16: Kirdomic Concept Code (enter card number 1 to 5) | K16: 2
B18: * | C18: Word Card Number (enter card number 1 or 2) | K18: 1
B20: * | C20: Action Value Code | K20: =_xlfn.CONCAT(K14,K16,K18) -> 621
C22: Intrinsic 'C' Value: ------> | K22: =SUMIF('Master Data'!$F$141:$F$292,'Check Value'!K20,'Master Data'!$G$141:$G$292) -> 12.652616
B24: Intrinsic Value by Action Grid Code
B26: Please Enter an Action Grid Code | K26: J
E28: Intrinsic 'C' Value by Grid Code
E30: F | F30: O | G30: C | H30: U | I30: S
D31: P | E31: =IF($K$26="Q",SUMIF('Master Data'!$F$141:$F$292,$K$20,'Master Data'!$H$141:$H$292),"") | F31: =IF($K$26="W",SUMIF('Master Data'!$F$141:$F$292,$K$20,'Master Data'!$M$141:$M$292),"") | G31: =IF($K$26="E",SUMIF('Master Data'!$F$141:$F$292,$K$20,'Master Data'!$R$141:$R$292),"") | H31: =IF($K$26="R",SUMIF('Master Data'!$F$141:$F$292,$K$20,'Master Data'!$W$141:$W$292),"") | I31: =IF($K$26="T",SUMIF('Master Data'!$F$141:$F$292,$K$20,'Master Data'!$AB$141:$AB$292),"")
D32: E | E32: =IF($K$26="A",SUMIF('Master Data'!$F$141:$F$292,$K$20,'Master Data'!$I$141:$I$292),"") | F32: =IF($K$26="S",SUMIF('Master Data'!$F$141:$F$292,$K$20,'Master Data'!$N$141:$N$292),"") | G32: =IF($K$26="D",SUMIF('Master Data'!$F$141:$F$292,$K$20,'Master Data'!$S$141:$S$292),"") | H32: =IF($K$26="F",SUMIF('Master Data'!$F$141:$F$292,$K$20,'Master Data'!$X$141:$X$292),"") | I32: =IF($K$26="G",SUMIF('Master Data'!$F$141:$F$292,$K$20,'Master Data'!$AC$141:$AC$292),"")
D33: A | E33: =IF($K$26="C",SUMIF('Master Data'!$F$141:$F$292,$K$20,'Master Data'!$J$141:$J$292),"") | F33: =IF($K$26="X",SUMIF('Master Data'!$F$141:$F$292,$K$20,'Master Data'!$O$141:$O$292),"") | G33: =IF($K$26="V",SUMIF('Master Data'!$F$141:$F$292,$K$20,'Master Data'!$T$141:$T$292),"") | H33: =IF($K$26="B",SUMIF('Master Data'!$F$141:$F$292,$K$20,'Master Data'!$Y$141:$Y$292),"") | I33: =IF($K$26="N",SUMIF('Master Data'!$F$141:$F$292,$K$20,'Master Data'!$AD$141:$AD$292),"")
D34: C | E34: =IF($K$26="Y",SUMIF('Master Data'!$F$141:$F$292,$K$20,'Master Data'!$K$141:$K$292),"") | F34: =IF($K$26="U",SUMIF('Master Data'!$F$141:$F$292,$K$20,'Master Data'!$P$141:$P$292),"") | G34: =IF($K$26="I",SUMIF('Master Data'!$F$141:$F$292,$K$20,'Master Data'!$U$141:$U$292),"") | H34: =IF($K$26="O",SUMIF('Master Data'!$F$141:$F$292,$K$20,'Master Data'!$Z$141:$Z$292),"") | I34: =IF($K$26="P",SUMIF('Master Data'!$F$141:$F$292,$K$20,'Master Data'!$AE$141:$AE$292),"")
D35: E | E35: =IF($K$26="H",SUMIF('Master Data'!$F$141:$F$292,$K$20,'Master Data'!$L$141:$L$292),"") | F35: =IF($K$26="J",SUMIF('Master Data'!$F$141:$F$292,$K$20,'Master Data'!$Q$141:$Q$292),"") -> 9.0981183 | G35: =IF($K$26="K",SUMIF('Master Data'!$F$141:$F$292,$K$20,'Master Data'!$V$141:$V$292),"") | H35: =IF($K$26="L",SUMIF('Master Data'!$F$141:$F$292,$K$20,'Master Data'!$AA$141:$AA$292),"") | I35: =IF($K$26="M",SUMIF('Master Data'!$F$141:$F$292,$K$20,'Master Data'!$AF$141:$AF$292),"")
E38: F | F38: O | G38: C | H38: U | I38: S
D39: P | E39: Q | F39: W | G39: E | H39: R | I39: T
D40: E | E40: A | F40: S | G40: D | H40: F | I40: G
D41: A | E41: C | F41: X | G41: V | H41: B | I41: N
D42: C | E42: Y | F42: U | G42: I | H42: O | I42: P
D43: E | E43: H | F43: J | G43: K | H43: L | I43: M
B47: Avalrem Unit Calculation
D49: Basic Formula
D50: Avalrem | F50: = | G50: C
G51: (a - i)
E54: C | G54: =K22 -> 12.652616
E55: a | G55: ='Pilot Formula Test'!M71 -> 1
E56: i | G56: ='Pilot Formula Test'!M89 -> 0.046280992
E58: Avalrem | G58: =G54/(G55-G56) -> 13.266608

Sheet Use Case Lab
A1: ACTION STATEMENT STRUCTURE QUALIFIED FOR AVALREM CONSIDERATION
E4: F | F4: O | G4: C | H4: U | I4: S
D5: P | E5: Q | F5: W | G5: E | H5: R | I5: T
D6: E | E6: A | F6: S | G6: D | H6: F | I6: G
D7: A | E7: C | F7: X | G7: V | H7: B | I7: N
D8: C | E8: Y | F8: U | G8: I | H8: O | I8: P
D9: E | E9: H | F9: J | G9: K | H9: L | I9: M
B12: Date | C12: Action Performed | D12: Result | E12: Action Value Evaluation
D13: Avalrem | E13: Action Word | F13: Context Code | G13: Kirdomic Code | H13: Action Order | I13: Action Grid Code | J13: Success Factor
F14: Big Questions | G14: IPI | H14: Intrinsic Value | I14: #Z | J14: Kdm
F15: [1-12] | G15: [1-5] | H15: [1 or 2] | I15: 25 Letters
B16: 45545 | C16: Follow up on outstanding JV for month-end close and suggest to the team what needs to be done.
D17: 25 | E17: Follow-up | F17: 8 | G17: 1 | H17: 1 | I17: I | J17: 1
D18: 28 | E18: Suggest | F18: 6 | G18: 2 | H18: 2 | I18: J | J18: 1
C19: Total Avalrem | D19: =SUM(D17:D18) -> 53
E22: Grid Code | F22: BQ Code | G22: 5 Principles
E23: A-Y | F23: 01-12 | G23: Color Code
D25: #Z | E25: S | F25: 4 | G25: GR
G29: Anxergy | H29: BL
G30: Exdysivity | H30: GR
G31: Avalremy | H31: RD
G32: Dexterience | H32: PK
G33: Atammayata | H33: YL

Sheet Q&A Matrix
B1: DYNAMIC WEIGHTING SYSTEM
B3: For a transactional action
B4: * | C4: Completed
B5: * | C5: Verified
G9: Kdm Multiplier | K9: To multipliy the calculated sub-Avalrem accumulated units
B11: Weight | D11: higher is better | G11: Kdm | M11: Impact | N11: in long term | P11: higher is better | U11: Time | V11: >= 1 | W11: Lower is better
E12: <1
B13: 12 Big Questions (B.Q.) | D13: Priority | E13: Weight by Priority to 12 | G13: Overall Transactional Success Factor | M13: Impact Level | N13: Kirdomicism Principle Factor | S13: Total by Level | U13: Time Factor = a
E14: Low 1 - High 12 | N14: Anxergy | O14: Exdysivity | P14: Dexterience | Q14: Avalremy | R14: Atammayata
B15: Question-1 | C15: World | D15: 1 | E15: =D15/$E$27 -> 0.082644628 | G15: * | H15: Exceptional | J15: 2 | M15: 12 | N15: 0.12 | O15: 0.12 | P15: 0.12 | Q15: 0.12 | R15: 0.12 | S15: =SUM(N15:R15) -> 0.6 | U15: * | V15: Future | W15: 1 | X15: Future implications
B16: Question-2 | C16: Country | D16: 2 | E16: =D16/$E$27 -> 0.16528926 | G16: * | H16: Excellent | J16: 1.5 | M16: 11 | N16: 0.11 | O16: 0.11 | P16: 0.11 | Q16: 0.11 | R16: 0.11 | S16: =SUM(N16:R16) -> 0.55 | U16: * | V16: Present | W16: 1.1 | X16: Present implications
B17: Question-3 | C17: Society | D17: 3 | E17: =D17/$E$27 -> 0.24793388 | G17: * | H17: Very good | J17: 1.2 | M17: 10 | N17: 0.1 | O17: 0.1 | P17: 0.1 | Q17: 0.1 | R17: 0.1 | S17: =SUM(N17:R17) -> 0.5 | U17: * | V17: Past | W17: 1.2 | X17: Past implications
B18: Question-4 | C18: Business | D18: 4 | E18: =D18/$E$27 -> 0.33057851 | G18: * | H18: Good | J18: 1 | M18: 9 | N18: 0.09 | O18: 0.09 | P18: 0.09 | Q18: 0.09 | R18: 0.09 | S18: =SUM(N18:R18) -> 0.45
B19: Question-5 | C19: Organization | D19: 5 | E19: =D19/$E$27 -> 0.41322314 | G19: * | H19: Fair | J19: 0.9 | M19: 8 | N19: 0.08 | O19: 0.08 | P19: 0.08 | Q19: 0.08 | R19: 0.08 | S19: =SUM(N19:R19) -> 0.4
B20: Question-6 | C20: Team | D20: 6 | E20: =D20/$E$27 -> 0.49586777 | G20: * | H20: Poor | J20: 0.5 | M20: 7 | N20: 0.07 | O20: 0.07 | P20: 0.07 | Q20: 0.07 | R20: 0.07 | S20: =SUM(N20:R20) -> 0.35
B21: Question-7 | C21: Product | D21: 7 | E21: =D21/$E$27 -> 0.5785124 | G21: * | H21: Very poor | J21: 0.1 | M21: 6 | N21: 0.06 | O21: 0.06 | P21: 0.06 | Q21: 0.06 | R21: 0.06 | S21: =SUM(N21:R21) -> 0.3
B22: Question-8 | C22: Process | D22: 8 | E22: =D22/$E$27 -> 0.66115702 | G22: * | H22: Threatening | J22: -0.5 | M22: 5 | N22: 0.05 | O22: 0.05 | P22: 0.05 | Q22: 0.05 | R22: 0.05 | S22: =SUM(N22:R22) -> 0.25
B23: Question-9 | C23: Problem | D23: 9 | E23: =D23/$E$27 -> 0.74380165 | G23: * | H23: Dangerous | J23: -1 | M23: 4 | N23: 0.04 | O23: 0.04 | P23: 0.04 | Q23: 0.04 | R23: 0.04 | S23: =SUM(N23:R23) -> 0.2
B24: Question-10 | C24: Uncertainty | D24: 10 | E24: =D24/$E$27 -> 0.82644628 | G24: * | H24: Terminate | J24: -2 | M24: 3 | N24: 0.03 | O24: 0.03 | P24: 0.03 | Q24: 0.03 | R24: 0.03 | S24: =SUM(N24:R24) -> 0.15
B25: Question-11 | C25: Completion | D25: 11 | E25: =D25/$E$27 -> 0.90909091 | M25: 2 | N25: 0.02 | O25: 0.02 | P25: 0.02 | Q25: 0.02 | R25: 0.02 | S25: =SUM(N25:R25) -> 0.1
B26: Question-12 | C26: Self | D26: 12 | E26: =D26/$E$27 -> 0.99173554 | M26: 1 | N26: 0.01 | O26: 0.01 | P26: 0.01 | Q26: 0.01 | R26: 0.01 | S26: =SUM(N26:R26) -> 0.05
B27: To add 0.1 to 12 to avoid weight = 1 | E27: 12.1 | M27: -1 | N27: =-N26 -> -0.01 | O27: =-O26 -> -0.01 | P27: =-P26 -> -0.01 | Q27: =-Q26 -> -0.01 | R27: =-R26 -> -0.01 | S27: =SUM(N27:R27) -> -0.05
M28: -2 | N28: =-N25 -> -0.02 | O28: =-O25 -> -0.02 | P28: =-P25 -> -0.02 | Q28: =-Q25 -> -0.02 | R28: =-R25 -> -0.02 | S28: =SUM(N28:R28) -> -0.1
B29: Based on: | M29: -3 | N29: =-N24 -> -0.03 | O29: =-O24 -> -0.03 | P29: =-P24 -> -0.03 | Q29: =-Q24 -> -0.03 | R29: =-R24 -> -0.03 | S29: =SUM(N29:R29) -> -0.15
B30: * | C30: Societal Needs | D30: Determined by AI governance system | M30: -4 | N30: =-N23 -> -0.04 | O30: =-O23 -> -0.04 | P30: =-P23 -> -0.04 | Q30: =-Q23 -> -0.04 | R30: =-R23 -> -0.04 | S30: =SUM(N30:R30) -> -0.2
M31: -5 | N31: =-N22 -> -0.05 | O31: =-O22 -> -0.05 | P31: =-P22 -> -0.05 | Q31: =-Q22 -> -0.05 | R31: =-R22 -> -0.05 | S31: =SUM(N31:R31) -> -0.25
M32: -6 | N32: =-N21 -> -0.06 | O32: =-O21 -> -0.06 | P32: =-P21 -> -0.06 | Q32: =-Q21 -> -0.06 | R32: =-R21 -> -0.06 | S32: =SUM(N32:R32) -> -0.3
M33: -7 | N33: =-N20 -> -0.07 | O33: =-O20 -> -0.07 | P33: =-P20 -> -0.07 | Q33: =-Q20 -> -0.07 | R33: =-R20 -> -0.07 | S33: =SUM(N33:R33) -> -0.35
M34: -8 | N34: =-N19 -> -0.08 | O34: =-O19 -> -0.08 | P34: =-P19 -> -0.08 | Q34: =-Q19 -> -0.08 | R34: =-R19 -> -0.08 | S34: =SUM(N34:R34) -> -0.4
M35: -9 | N35: =-N18 -> -0.09 | O35: =-O18 -> -0.09 | P35: =-P18 -> -0.09 | Q35: =-Q18 -> -0.09 | R35: =-R18 -> -0.09 | S35: =SUM(N35:R35) -> -0.45
M36: -10 | N36: =-N17 -> -0.1 | O36: =-O17 -> -0.1 | P36: =-P17 -> -0.1 | Q36: =-Q17 -> -0.1 | R36: =-R17 -> -0.1 | S36: =SUM(N36:R36) -> -0.5
M37: -11 | N37: =-N16 -> -0.11 | O37: =-O16 -> -0.11 | P37: =-P16 -> -0.11 | Q37: =-Q16 -> -0.11 | R37: =-R16 -> -0.11 | S37: =SUM(N37:R37) -> -0.55
M38: -12 | N38: =-N15 -> -0.12 | O38: =-O15 -> -0.12 | P38: =-P15 -> -0.12 | Q38: =-Q15 -> -0.12 | R38: =-R15 -> -0.12 | S38: =SUM(N38:R38) -> -0.6
B40: Note:
B41: Completed and verified actions are recorded by blockchain-like system to create a transparent and immutable ledger | N41: Anxergy | O41: Exdysivity | P41: Dexterience | Q41: Avalremy | R41: Atammayata
B42: of every individual's contribution for accumulation of total "Avalrem wealth" over time.
N43: Effectivity | O43: Innovation
B44: Enable a marketplace of needs wit a system governing how Avalrem can be used to acquire specific service or goods.
B46: AI will match individuals with needs to those who can perform necessary actions. | N46: Confirm by 7 levels of actions to replace subjectivity.

Sheet Pilot Formula Test
B2: Avalrem = | C2: C
C3: (a - i)
B6: C | C6: Future value of action impacts
B8: a | C8: Time score - lower is better
B10: i | C10: Impact % - higher is better
C16: n
B17: Total Avalrem | C17: #VALUE! | D17: Avalrem i | E17: * | F17: Kdm
C18: i=1
B22: Avalrem = | C22: C
C23: (a - i)
B27: C | C27: Future value of action impact
B29: a | C29: Discount rate of future
B31: i | C31: Impact rate of future consequence
B33: Kdm | C33: Multiplier of Avalrem
I44: Action Statement:
I46: In order to inprove productivity of the production line, the responsible person must change
I47: the process by eliminate the existing line layout before installing a new line.
I52: Future value of action impact "C"
J54: Applying Kirdomic Card Tool:
I56: * | J56: Kirdomic Card Number (enter card number 1 to 12) | O56: ='Check Value'!K14 -> 6 | P56: VI
I57: * | J57: Kirdomic Concept Code (enter card number 1 to 5) | O57: ='Check Value'!K16 -> 2 | P57: Exdysivity
I58: * | J58: Word Card Number (enter card number 1 or 2) | O58: ='Check Value'!K18 -> 1 | P58: ='Check Value'!K6 -> Eliminate
I59: * | J59: Action Value Code | O59: ='Check Value'!K20 -> 621 | P59: Master
J61: Intrinsic Value: ------> | O61: ='Check Value'!K22 -> 12.652616
I67: Finding value "a"
I69: a | J69: Time factor | K69: Must be >= | L69: 1 | N69: Higher is better
K71: a | L71: = | M71: ='Q&A Matrix'!W15 -> 1
I76: Finding value "I"
I78: X | J78: 12 BQ | K78: Weight | N78: Higher is better
I79: Y | J79: 5 principles | K79: Impact | L79: 1-12 | M79: levels | N79: Higher is better
I81: X*Y | J81: = i | N81: Lower is better in formula result
I83: Assignment of Factor Value:
J85: X weight | K85: Y impact
J86: ='Q&A Matrix'!B22 -> Question-8 | K86: ='Q&A Matrix'!O14 -> Exdysivity
J87: ='Q&A Matrix'!E22 -> 0.66115702 | K87: ='Q&A Matrix'!N20 -> 0.07
K89: i | L89: = | M89: =J87*K87 -> 0.046280992 | W89: Lower than FV | Z89: Higher than FV (actual is better than expected)
U90: Scenario-Base | V90: Scenario-Lowest PV | W90: Scenario-1 | X90: Scenario-2 | Y90: Scenario-3 | Z90: Scenario-4 | AA90: Scenario-5 | AB90: Scenario-6 | AC90: Scenario-7 | AD90: Scenario-8 | AE90: Scenario-9 | AF90: Scenario-10
S92: C | U92: 1000 | V92: 1000 | W92: 1000 | X92: =W92 -> 1000 | Y92: =X92 -> 1000 | Z92: =Y92 -> 1000 | AA92: =Z92 -> 1000 | AB92: =AA92 -> 1000 | AC92: =AB92 -> 1000 | AD92: =AC92 -> 1000 | AE92: =AD92 -> 1000 | AF92: =AE92 -> 1000
R94: Time | S94: a | T94: >= 1 | U94: 1 | V94: 1000 | W94: 1.1 | X94: 1.2 | Y94: 1.3 | Z94: 1.4 | AA94: 1.5 | AB94: 1.6 | AC94: 1.7 | AD94: 1.8 | AE94: 1.9 | AF94: 2 | AG94: Lower is better
S96: C / a | U96: =U92/U94 -> 1000 | V96: =V92/V94 -> 1 | W96: =W92/W94 -> 909.09091 | X96: =X92/X94 -> 833.33333 | Y96: =Y92/Y94 -> 769.23077 | Z96: =Z92/Z94 -> 714.28571 | AA96: =AA92/AA94 -> 666.66667 | AB96: =AB92/AB94 -> 625 | ... AF96: =AF92/AF94 -> 500
...

Sheet AI Prompt
F5: Context | G5: C | H5: Statement of actions?
F18: Rule | H18: Identify the time factor | O18: Time | R18: >= 1 | S18: higher is better
G20: a | Q20: Time Factor = a
H22: Indicate the time factor that best reflects the impact of the statement of action. | Q22: * | R22: Future | S22: 1.2 | T22: Future implications
Q23: * | R23: Present | S23: 1.1 | T23: Present implications
Q24: * | R24: Past | S24: 1 | T24: Past implications
Q29: There are 12 tables of this type with different weight depending on a particular circumstance of a user.
G30: x | H30: Select the big questions | L30: 1-12 | O30: Weight | Q30: 12 Big Questions (B.Q.) | S30: Question-1 | T30: Question-2 | U30: Question-3 | V30: Question-4 | W30: Question-5 | X30: Question-6 | Y30: Question-7 | Z30: Question-8 | AA30: Question-9 | AB30: Question-10 | AC30: Question-11 | AD30: Question-12 | AE30: To add 0.1 to 12 to avoid weight = 1
O31: higher is better | P31: <1 | S31: World | T31: Country | U31: Society | V31: Business | W31: Organization | X31: Team | Y31: Product | Z31: Process | AA31: Problem | AB31: Uncertainty | AC31: Completion | AD31: Self
Q32: Priority | S32: 1 | T32: 2 | U32: 3 | V32: 4 | W32: 5 | X32: 6 | Y32: 7 | Z32: 8 | AA32: 9 | AB32: 10 | AC32: 11 | AD32: 12
P33: =S31 -> World | Q33: Weight by Priority to 12 | R33: Low 1 - High 12 | S33: =S32/$AE$33 -> 0.082644628 | T33: =T32/$AE$33 -> 0.16528926 | U33: =U32/$AE$33 -> 0.24793388 | V33: =V32/$AE$33 -> 0.33057851 | W33: =W32/$AE$33 -> 0.41322314 | X33: =X32/$AE$33 -> 0.49586777 | Y33: =Y32/$AE$33 -> 0.5785124 | Z33: =Z32/$AE$33 -> 0.66115702 | ... AD33: =AD32/$AE$33 -> 0.99173554 | AE33: 12.1
H34: To identify the x impact, user must locate the general table first and then look for the | P34: General by row/User by column
H35: column in response to the action statement before identifying the weight figure. | Q35: 12 Big Questions (B.Q.) | S35: Question-1 | T35: Question-2 | U35: Question-3 | V35: Question-4 | W35: Question-5 | X35: Question-6 | Y35: Question-7 | Z35: Question-8 | AA35: Question-9 | AB35: Question-10 | AC35: Question-11 | AD35: Question-12 | AE35: To add 0.1 to 12 to avoid weight = 1
S36: World | T36: Country | U36: Society | V36: Business | W36: Organization | X36: Team | Y36: Product | Z36: Process | AA36: Problem | AB36: Uncertainty | AC36: Completion | AD36: Self
Q37: Priority | S37: 12 | T37: 1 | U37: 2 | V37: 3 | W37: 4 | X37: 5 | Y37: 6 | Z37: 7 | AA37: 8 | AB37: 9 | AC37: 10 | AD37: 11
P38: =T36 -> Country | Q38: Weight by Priority to 12 | R38: Low 1 - High 12 | S38: =S37/$AE$33 -> 0.99173554 | T38: =T37/$AE$33 -> 0.082644628 | U38: =U37/$AE$33 -> 0.16528926 | V38: =V37/$AE$33 -> 0.24793388 | W38: =W37/$AE$33 -> 0.33057851 | X38: =X37/$AE$33 -> 0.41322314 | Y38: =Y37/$AE$33 -> 0.49586777 | Z38: =Z37/$AE$33 -> 0.5785124 | ... AD38: =AD37/$AE$33 -> 0.90909091 | AE38: 12.1
P39: General by row/User by column
Q40: 12 Big Questions (B.Q.) | S40: Question-1 | T40: Question-2 | U40: Question-3 | V40: Question-4 | W40: Question-5 | X40: Question-6 | Y40: Question-7 | Z40: Question-8 | AA40: Question-9 | AB40: Question-10 | AC40: Question-11 | AD40: Question-12 | AE40: To add 0.1 to 12 to avoid weight = 1
S41: World | T41: Country | U41: Society | V41: Business | W41: Organization | X41: Team | Y41: Product | Z41: Process | AA41: Problem | AB41: Uncertainty | AC41: Completion | AD41: Self
Q42: Priority | S42: 11 | T42: 12 | U42: 1 | V42: 2 | W42: 3 | X42: 4 | Y42: 5 | Z42: 6 | AA42: 7 | AB42: 8 | AC42: 9 | AD42: 10
P43: =U41 -> Society | Q43: Weight by Priority to 12 | R43: Low 1 - High 12 | S43: =S42/$AE$33 -> 0.90909091 | T43: =T42/$AE$33 -> 0.99173554 | U43: =U42/$AE$33 -> 0.082644628 | V43: =V42/$AE$33 -> 0.16528926 | W43: =W42/$AE$33 -> 0.24793388 | X43: =X42/$AE$33 -> 0.33057851 | Y43: =Y42/$AE$33 -> 0.41322314 | Z43: =Z42/$AE$33 -> 0.49586777 | ... AD43: =AD42/$AE$33 -> 0.82644628 | AE43: 12.1
P44: General by row/User by column
Q45: 12 Big Questions (B.Q.) | S45: Question-1 | T45: Question-2 | U45: Question-3 | V45: Question-4 | W45: Question-5 | X45: Question-6 | Y45: Question-7 | Z45: Question-8 | AA45: Question-9 | AB45: Question-10 | AC45: Question-11 | AD45: Question-12 | AE45: To add 0.1 to 12 to avoid weight = 1
S46: World | T46: Country | U46: Society | V46: Business | W46: Organization | X46: Team | Y46: Product | Z46: Process | AA46: Problem | AB46: Uncertainty | AC46: Completion | AD46: Self
Q47: Priority | S47: 10 | T47: 11 | U47: 12 | V47: 1 | W47: 2 | X47: 3 | Y47: 4 | Z47: 5 | AA47: 6 | AB47: 7 | AC47: 8 | AD47: 9
P48: =V46 -> Business | Q48: Weight by Priority to 12 | R48: Low 1 - High 12 | S48: =S47/$AE$33 -> 0.82644628 | T48: =T47/$AE$33 -> 0.90909091 | U48: =U47/$AE$33 -> 0.99173554 | V48: =V47/$AE$33 -> 0.082644628 | W48: =W47/$AE$33 -> 0.16528926 | X48: =X47/$AE$33 -> 0.24793388 | Y48: =Y47/$AE$33 -> 0.33057851 | Z48: =Z47/$AE$33 -> 0.41322314 | ... AD48: =AD47/$AE$33 -> 0.74380165 | AE48: 12.1
P49: General by row/User by column
Q50: 12 Big Questions (B.Q.) | S50: Question-1 | T50: Question-2 | U50: Question-3 | V50: Question-4 | W50: Question-5 | X50: Question-6 | Y50: Question-7 | Z50: Question-8 | AA50: Question-9 | AB50: Question-10 | AC50: Question-11 | AD50: Question-12 | AE50: To add 0.1 to 12 to avoid weight = 1
S51: World | T51: Country | U51: Society | V51: Business | W51: Organization | X51: Team | Y51: Product | Z51: Process | AA51: Problem | AB51: Uncertainty | AC51: Completion | AD51: Self
Q52: Priority | S52: 9 | T52: 10 | U52: 11 | V52: 12 | W52: 1 | X52: 2 | Y52: 3 | Z52: 4 | AA52: 5 | AB52: 6 | AC52: 7 | AD52: 8
P53: =W51 -> Organization | Q53: Weight by Priority to 12 | R53: Low 1 - High 12 | S53: =S52/$AE$33 -> 0.74380165 | T53: =T52/$AE$33 -> 0.82644628 | U53: =U52/$AE$33 -> 0.90909091 | V53: =V52/$AE$33 -> 0.99173554 | W53: =W52/$AE$33 -> 0.082644628 | X53: =X52/$AE$33 -> 0.16528926 | Y53: =Y52/$AE$33 -> 0.24793388 | Z53: =Z52/$AE$33 -> 0.33057851 | ... AD53: =AD52/$AE$33 -> 0.66115702 | AE53: 12.1
P54: General by row/User by column
Q55: 12 Big Questions (B.Q.) | S55: Question-1 | T55: Question-2 | U55: Question-3 | V55: Question-4 | W55: Question-5 | X55: Question-6 | Y55: Question-7 | Z55: Question-8 | AA55: Question-9 | AB55: Question-10 | AC55: Question-11 | AD55: Question-12 | AE55: To add 0.1 to 12 to avoid weight = 1
S56: World | T56: Country | U56: Society | V56: Business | W56: Organization | X56: Team | Y56: Product | Z56: Process | AA56: Problem | AB56: Uncertainty | AC56: Completion | AD56: Self
Q57: Priority | S57: 8 | T57: 9 | U57: 10 | V57: 11 | W57: 12 | X57: 1 | Y57: 2 | Z57: 3 | AA57: 4 | AB57: 5 | AC57: 6 | AD57: 7
P58: =X56 -> Team | Q58: Weight by Priority to 12 | R58: Low 1 - High 12 | S58: =S57/$AE$33 -> 0.66115702 | T58: =T57/$AE$33 -> 0.74380165 | U58: =U57/$AE$33 -> 0.82644628 | V58: =V57/$AE$33 -> 0.90909091 | W58: =W57/$AE$33 -> 0.99173554 | X58: =X57/$AE$33 -> 0.082644628 | Y58: =Y57/$AE$33 -> 0.16528926 | Z58: =Z57/$AE$33 -> 0.24793388 | ... AD58: =AD57/$AE$33 -> 0.5785124 | AE58: 12.1
P59: General by row/User by column
Q60: 12 Big Questions (B.Q.) | S60: Question-1 | T60: Question-2 | U60: Question-3 | V60: Question-4 | W60: Question-5 | X60: Question-6 | Y60: Question-7 | Z60: Question-8 | AA60: Question-9 | AB60: Question-10 | AC60: Question-11 | AD60: Question-12 | AE60: To add 0.1 to 12 to avoid weight = 1
S61: World | T61: Country | U61: Society | V61: Business | W61: Organization | X61: Team | Y61: Product | Z61: Process | AA61: Problem | AB61: Uncertainty | AC61: Completion | AD61: Self
Q62: Priority | S62: 7 | T62: 8 | U62: 9 | V62: 10 | W62: 11 | X62: 12 | Y62: 1 | Z62: 2 | AA62: 3 | AB62: 4 | AC62: 5 | AD62: 6
...

Sheet 7 Action Levels

Sheet Standard Avalrem Table
A1: STANDARD AVALREM BY CARD & COLOR
B3: Calculate from 25 action grid value and average by dividing with 25
B5: Calculator Formula | J5: Impact Factor Factor | L5: ='Success Rate'!E9 -> 2 | M5: ='Success Rate'!C9 -> Exceptional | R5: At Success Factor | T5: ='Success Rate'!E10 -> 1.5 | U5: ='Success Rate'!C10 -> Excellent | Z5: At Success Factor | AB5: ='Success Rate'!E11 -> 1.2 | AC5: ='Success Rate'!C11 -> Very good | AH5: At Success Factor | AJ5: ='Success Rate'!E12 -> 1 | AK5: ='Success Rate'!C12 -> Good
B7: Card No. | C7: Anxergy | D7: Exdysivity | E7: Dexterience | F7: Avalremy | G7: Atammayata | J7: Card No. | K7: Anxergy | L7: Exdysivity | M7: Dexterience | N7: Avalremy | O7: Atammayata | R7: Card No. | S7: Anxergy | T7: Exdysivity | U7: Dexterience | V7: Avalremy | W7: Atammayata | Z7: Card No. | AA7: Anxergy | AB7: Exdysivity | AC7: Dexterience | AD7: Avalremy | AE7: Atammayata | AH7: Card No. | AI7: Anxergy | AJ7: Exdysivity | AK7: Dexterience | AL7: Avalremy | AM7: Atammayata
C8: 2 WORDS COMBINED VALUE | K8: 2 WORDS COMBINED VALUE | S8: 2 WORDS COMBINED VALUE | AA8: 2 WORDS COMBINED VALUE | AI8: 2 WORDS COMBINED VALUE
B9: 1 | C9: =C25+C40 -> 43.024632 | D9: =D25+D40 -> 41.304455 | E9: =E25+E40 -> 41.496251 | F9: =F25+F40 -> 40.919825 | G9: =G25+G40 -> 40.050079 | J9: 1 | K9: =$L$5*C9 -> 86.049264 | L9: =$L$5*D9 -> 82.60891 | M9: =$L$5*E9 -> 82.992503 | N9: =$L$5*F9 -> 81.839651 | O9: =$L$5*G9 -> 80.100158 | R9: 1 | S9: =$T$5*C9 -> 64.536948 | T9: =$T$5*D9 -> 61.956682 | U9: =$T$5*E9 -> 62.244377 | V9: =$T$5*F9 -> 61.379738 | W9: =$T$5*G9 -> 60.075118 | Z9: 1 | AA9: =$AB$5*C9 -> 51.629559 | AB9: =$AB$5*D9 -> 49.565346 | AC9: =$AB$5*E9 -> 49.795502 | AD9: =$AB$5*F9 -> 49.103791 | AE9: =$AB$5*G9 -> 48.060095 | AH9: 1 | AI9: =$AJ$5*C9 -> 43.024632 | AJ9: =$AJ$5*D9 -> 41.304455 | AK9: =$AJ$5*E9 -> 41.496251 | AL9: =$AJ$5*F9 -> 40.919825 | AM9: =$AJ$5*G9 -> 40.050079
B10: 2 | C10: =C26+C41 -> 47.279475 | D10: =D26+D41 -> 44.990974 | E10: =E26+E41 -> 45.59935 | F10: =F26+F41 -> 44.370263 | G10: =G26+G41 -> 43.938674 | J10: 2 | K10: =$L$5*C10 -> 94.558949 | L10: =$L$5*D10 -> 89.981949 | M10: =$L$5*E10 -> 91.1987 | N10: =$L$5*F10 -> 88.740527 | O10: =$L$5*G10 -> 87.877347 | R10: 2 | S10: =$T$5*C10 -> 70.919212 | T10: =$T$5*D10 -> 67.486462 | U10: =$T$5*E10 -> 68.399025 | V10: =$T$5*F10 -> 66.555395 | W10: =$T$5*G10 -> 65.908011 | Z10: 2 | AA10: =$AB$5*C10 -> 56.735369 | AB10: =$AB$5*D10 -> 53.989169 | AC10: =$AB$5*E10 -> 54.71922 | AD10: =$AB$5*F10 -> 53.244316 | AE10: =$AB$5*G10 -> 52.726408 | AH10: 2 | AI10: =$AJ$5*C10 -> 47.279475 | AJ10: =$AJ$5*D10 -> 44.990974 | AK10: =$AJ$5*E10 -> 45.59935 | AL10: =$AJ$5*F10 -> 44.370263 | AM10: =$AJ$5*G10 -> 43.938674
B11: 3 | C11: =C27+C42 -> 48.616182 | D11: =D27+D42 -> 47.055372 | E11: =E27+E42 -> 46.964332 | F11: =F27+F42 -> 45.987895 | G11: =G27+G42 -> 45.363963 | J11: 3 | K11: =$L$5*C11 -> 97.232365 | L11: =$L$5*D11 -> 94.110744 | M11: =$L$5*E11 -> 93.928664 | N11: =$L$5*F11 -> 91.97579 | O11: =$L$5*G11 -> 90.727927 | R11: 3 | S11: =$T$5*C11 -> 72.924274 | T11: =$T$5*D11 -> 70.583058 | U11: =$T$5*E11 -> 70.446498 | V11: =$T$5*F11 -> 68.981842 | W11: =$T$5*G11 -> 68.045945 | Z11: 3 | AA11: =$AB$5*C11 -> 58.339419 | AB11: =$AB$5*D11 -> 56.466446 | AC11: =$AB$5*E11 -> 56.357199 | AD11: =$AB$5*F11 -> 55.185474 | AE11: =$AB$5*G11 -> 54.436756 | AH11: 3 | AI11: =$AJ$5*C11 -> 48.616182 | AJ11: =$AJ$5*D11 -> 47.055372 | AK11: =$AJ$5*E11 -> 46.964332 | AL11: =$AJ$5*F11 -> 45.987895 | AM11: =$AJ$5*G11 -> 45.363963
B12: 4 | C12: =C28+C43 -> 49.852081 | D12: =D28+D43 -> 47.344467 | E12: =E28+E43 -> 47.408548 | F12: =F28+F43 -> 46.08407 | G12: =G28+G43 -> 46.037439 | J12: 4 | K12: =$L$5*C12 -> 99.704162 | L12: =$L$5*D12 -> 94.688935 | M12: =$L$5*E12 -> 94.817096 | N12: =$L$5*F12 -> 92.168141 | O12: =$L$5*G12 -> 92.074878 | R12: 4 | S12: =$T$5*C12 -> 74.778121 | T12: =$T$5*D12 -> 71.016701 | U12: =$T$5*E12 -> 71.112822 | V12: =$T$5*F12 -> 69.126105 | W12: =$T$5*G12 -> 69.056158 | Z12: 4 | AA12: =$AB$5*C12 -> 59.822497 | AB12: =$AB$5*D12 -> 56.813361 | AC12: =$AB$5*E12 -> 56.890258 | AD12: =$AB$5*F12 -> 55.300884 | AE12: =$AB$5*G12 -> 55.244927 | AH12: 4 | AI12: =$AJ$5*C12 -> 49.852081 | AJ12: =$AJ$5*D12 -> 47.344467 | AK12: =$AJ$5*E12 -> 47.408548 | AL12: =$AJ$5*F12 -> 46.08407 | AM12: =$AJ$5*G12 -> 46.037439
B13: 5 | C13: =C29+C44 -> 45.597239 | D13: =D29+D44 -> 43.657948 | E13: =E29+E44 -> 43.305449 | F13: =F29+F44 -> 42.633632 | G13: =G29+G44 -> 42.148844 | J13: 5 | K13: =$L$5*C13 -> 91.194477 | L13: =$L$5*D13 -> 87.315896 | M13: =$L$5*E13 -> 86.610899 | N13: =$L$5*F13 -> 85.267264 | O13: =$L$5*G13 -> 84.297688 | R13: 5 | S13: =$T$5*C13 -> 68.395858 | T13: =$T$5*D13 -> 65.486922 | U13: =$T$5*E13 -> 64.958174 | V13: =$T$5*F13 -> 63.950448 | W13: =$T$5*G13 -> 63.223266 | Z13: 5 | AA13: =$AB$5*C13 -> 54.716686 | AB13: =$AB$5*D13 -> 52.389538 | AC13: =$AB$5*E13 -> 51.966539 | AD13: =$AB$5*F13 -> 51.160359 | AE13: =$AB$5*G13 -> 50.578613 | AH13: 5 | AI13: =$AJ$5*C13 -> 45.597239 | AJ13: =$AJ$5*D13 -> 43.657948 | AK13: =$AJ$5*E13 -> 43.305449 | AL13: =$AJ$5*F13 -> 42.633632 | AM13: =$AJ$5*G13 -> 42.148844
B14: 6 | C14: =C30+C45 -> 44.260531 | D14: =D30+D45 -> 41.59355 | E14: =E30+E45 -> 41.940467 | F14: =F30+F45 -> 41.016001 | G14: =G30+G45 -> 40.723555 | J14: 6 | K14: =$L$5*C14 -> 88.521062 | L14: =$L$5*D14 -> 83.1871 | M14: =$L$5*E14 -> 83.880934 | N14: =$L$5*F14 -> 82.032002 | O14: =$L$5*G14 -> 81.447109 | R14: 6 | S14: =$T$5*C14 -> 66.390796 | T14: =$T$5*D14 -> 62.390325 | U14: =$T$5*E14 -> 62.910701 | V14: =$T$5*F14 -> 61.524001 | W14: =$T$5*G14 -> 61.085332 | Z14: 6 | AA14: =$AB$5*C14 -> 53.112637 | AB14: =$AB$5*D14 -> 49.91226 | AC14: =$AB$5*E14 -> 50.328561 | AD14: =$AB$5*F14 -> 49.219201 | AE14: =$AB$5*G14 -> 48.868265 | AH14: 6 | AI14: =$AJ$5*C14 -> 44.260531 | AJ14: =$AJ$5*D14 -> 41.59355 | AK14: =$AJ$5*E14 -> 41.940467 | AL14: =$AJ$5*F14 -> 41.016001 | AM14: =$AJ$5*G14 -> 40.723555
B15: 7 | C15: =C31+C46 -> 43.024632 | D15: =D31+D46 -> 41.304455 | E15: =E31+E46 -> 41.496251 | F15: =F31+F46 -> 40.919825 | G15: =G31+G46 -> 40.050079 | J15: 7 | K15: =$L$5*C15 -> 86.049264 | L15: =$L$5*D15 -> 82.60891 | M15: =$L$5*E15 -> 82.992503 | N15: =$L$5*F15 -> 81.839651 | O15: =$L$5*G15 -> 80.100158 | R15: 7 | S15: =$T$5*C15 -> 64.536948 | T15: =$T$5*D15 -> 61.956682 | U15: =$T$5*E15 -> 62.244377 | V15: =$T$5*F15 -> 61.379738 | W15: =$T$5*G15 -> 60.075118 | Z15: 7 | AA15: =$AB$5*C15 -> 51.629559 | AB15: =$AB$5*D15 -> 49.565346 | AC15: =$AB$5*E15 -> 49.795502 | AD15: =$AB$5*F15 -> 49.103791 | AE15: =$AB$5*G15 -> 48.060095 | AH15: 7 | AI15: =$AJ$5*C15 -> 43.024632 | AJ15: =$AJ$5*D15 -> 41.304455 | AK15: =$AJ$5*E15 -> 41.496251 | AL15: =$AJ$5*F15 -> 40.919825 | AM15: =$AJ$5*G15 -> 40.050079
B16: 8 | C16: =C32+C47 -> 47.279475 | D16: =D32+D47 -> 44.990974 | E16: =E32+E47 -> 45.59935 | F16: =F32+F47 -> 44.370263 | G16: =G32+G47 -> 43.938674 | J16: 8 | K16: =$L$5*C16 -> 94.558949 | L16: =$L$5*D16 -> 89.981949 | M16: =$L$5*E16 -> 91.1987 | N16: =$L$5*F16 -> 88.740527 | O16: =$L$5*G16 -> 87.877347 | R16: 8 | S16: =$T$5*C16 -> 70.919212 | T16: =$T$5*D16 -> 67.486462 | U16: =$T$5*E16 -> 68.399025 | V16: =$T$5*F16 -> 66.555395 | W16: =$T$5*G16 -> 65.908011 | Z16: 8 | AA16: =$AB$5*C16 -> 56.735369 | AB16: =$AB$5*D16 -> 53.989169 | AC16: =$AB$5*E16 -> 54.71922 | AD16: =$AB$5*F16 -> 53.244316 | AE16: =$AB$5*G16 -> 52.726408 | AH16: 8 | AI16: =$AJ$5*C16 -> 47.279475 | AJ16: =$AJ$5*D16 -> 44.990974 | AK16: =$AJ$5*E16 -> 45.59935 | AL16: =$AJ$5*F16 -> 44.370263 | AM16: =$AJ$5*G16 -> 43.938674
B17: 9 | C17: =C33+C48 -> 48.616182 | D17: =D33+D48 -> 47.055372 | E17: =E33+E48 -> 46.964332 | F17: =F33+F48 -> 45.987895 | G17: =G33+G48 -> 45.363963 | J17: 9 | K17: =$L$5*C17 -> 97.232365 | L17: =$L$5*D17 -> 94.110744 | M17: =$L$5*E17 -> 93.928664 | N17: =$L$5*F17 -> 91.97579 | O17: =$L$5*G17 -> 90.727927 | R17: 9 | S17: =$T$5*C17 -> 72.924274 | T17: =$T$5*D17 -> 70.583058 | U17: =$T$5*E17 -> 70.446498 | V17: =$T$5*F17 -> 68.981842 | W17: =$T$5*G17 -> 68.045945 | Z17: 9 | AA17: =$AB$5*C17 -> 58.339419 | AB17: =$AB$5*D17 -> 56.466446 | AC17: =$AB$5*E17 -> 56.357199 | AD17: =$AB$5*F17 -> 55.185474 | AE17: =$AB$5*G17 -> 54.436756 | AH17: 9 | AI17: =$AJ$5*C17 -> 48.616182 | AJ17: =$AJ$5*D17 -> 47.055372 | AK17: =$AJ$5*E17 -> 46.964332 | AL17: =$AJ$5*F17 -> 45.987895 | AM17: =$AJ$5*G17 -> 45.363963
B18: 10 | C18: =C34+C49 -> 49.852081 | D18: =D34+D49 -> 47.344467 | E18: =E34+E49 -> 47.408548 | F18: =F34+F49 -> 46.08407 | G18: =G34+G49 -> 46.037439 | J18: 10 | K18: =$L$5*C18 -> 99.704162 | L18: =$L$5*D18 -> 94.688935 | M18: =$L$5*E18 -> 94.817096 | N18: =$L$5*F18 -> 92.168141 | O18: =$L$5*G18 -> 92.074878 | R18: 10 | S18: =$T$5*C18 -> 74.778121 | T18: =$T$5*D18 -> 71.016701 | U18: =$T$5*E18 -> 71.112822 | V18: =$T$5*F18 -> 69.126105 | W18: =$T$5*G18 -> 69.056158 | Z18: 10 | AA18: =$AB$5*C18 -> 59.822497 | AB18: =$AB$5*D18 -> 56.813361 | AC18: =$AB$5*E18 -> 56.890258 | AD18: =$AB$5*F18 -> 55.300884 | AE18: =$AB$5*G18 -> 55.244927 | AH18: 10 | AI18: =$AJ$5*C18 -> 49.852081 | AJ18: =$AJ$5*D18 -> 47.344467 | AK18: =$AJ$5*E18 -> 47.408548 | AL18: =$AJ$5*F18 -> 46.08407 | AM18: =$AJ$5*G18 -> 46.037439
B19: 11 | C19: =C35+C50 -> 45.597239 | D19: =D35+D50 -> 43.657948 | E19: =E35+E50 -> 43.305449 | F19: =F35+F50 -> 42.633632 | G19: =G35+G50 -> 42.148844 | J19: 11 | K19: =$L$5*C19 -> 91.194477 | L19: =$L$5*D19 -> 87.315896 | M19: =$L$5*E19 -> 86.610899 | N19: =$L$5*F19 -> 85.267264 | O19: =$L$5*G19 -> 84.297688 | R19: 11 | S19: =$T$5*C19 -> 68.395858 | T19: =$T$5*D19 -> 65.486922 | U19: =$T$5*E19 -> 64.958174 | V19: =$T$5*F19 -> 63.950448 | W19: =$T$5*G19 -> 63.223266 | Z19: 11 | AA19: =$AB$5*C19 -> 54.716686 | AB19: =$AB$5*D19 -> 52.389538 | AC19: =$AB$5*E19 -> 51.966539 | AD19: =$AB$5*F19 -> 51.160359 | AE19: =$AB$5*G19 -> 50.578613 | AH19: 11 | AI19: =$AJ$5*C19 -> 45.597239 | AJ19: =$AJ$5*D19 -> 43.657948 | AK19: =$AJ$5*E19 -> 43.305449 | AL19: =$AJ$5*F19 -> 42.633632 | AM19: =$AJ$5*G19 -> 42.148844
B20: 12 | C20: =C36+C51 -> 44.260531 | D20: =D36+D51 -> 41.59355 | E20: =E36+E51 -> 41.940467 | F20: =F36+F51 -> 41.016001 | G20: =G36+G51 -> 40.723555 | J20: 12 | K20: =$L$5*C20 -> 88.521062 | L20: =$L$5*D20 -> 83.1871 | M20: =$L$5*E20 -> 83.880934 | N20: =$L$5*F20 -> 82.032002 | O20: =$L$5*G20 -> 81.447109 | R20: 12 | S20: =$T$5*C20 -> 66.390796 | T20: =$T$5*D20 -> 62.390325 | U20: =$T$5*E20 -> 62.910701 | V20: =$T$5*F20 -> 61.524001 | W20: =$T$5*G20 -> 61.085332 | Z20: 12 | AA20: =$AB$5*C20 -> 53.112637 | AB20: =$AB$5*D20 -> 49.91226 | AC20: =$AB$5*E20 -> 50.328561 | AD20: =$AB$5*F20 -> 49.219201 | AE20: =$AB$5*G20 -> 48.868265 | AH20: 12 | AI20: =$AJ$5*C20 -> 44.260531 | AJ20: =$AJ$5*D20 -> 41.59355 | AK20: =$AJ$5*E20 -> 41.940467 | AL20: =$AJ$5*F20 -> 41.016001 | AM20: =$AJ$5*G20 -> 40.723555
B23: Word-1 Standard Value | J23: Word-1 Standard Value | R23: Word-1 Standard Value | Z23: Word-1 Standard Value | AH23: Word-1 Standard Value
B24: Card No. | C24: Anxergy | D24: Exdysivity | E24: Dexterience | F24: Avalremy | G24: Atammayata | J24: Card No. | K24: Anxergy | L24: Exdysivity | M24: Dexterience | N24: Avalremy | O24: Atammayata | R24: Card No. | S24: Anxergy | T24: Exdysivity | U24: Dexterience | V24: Avalremy | W24: Atammayata | Z24: Card No. | AA24: Anxergy | AB24: Exdysivity | AC24: Dexterience | AD24: Avalremy | AE24: Atammayata | AH24: Card No. | AI24: Anxergy | AJ24: Exdysivity | AK24: Dexterience | AL24: Avalremy | AM24: Atammayata
B25: 1 | C25: =('Detailed Avalerem Tables'!X23+'Detailed Avalerem Tables'!X72+'Detailed Avalerem Tables'!X120+'Detailed Avalerem Tables'!X168+'Detailed Avalerem Tables'!X216+'Detailed Avalerem Tables'!AZ23+'Detailed Avalerem Tables'!AZ72+'Detailed Avalerem Tables'!AZ120+'Detailed Avalerem Tables'!AZ168+'Detailed Avalerem Tables'!AZ216+'Detailed Avalerem Tables'!CB23+'Detailed Avalerem Tables'!CB72+'Detailed Avalerem Tables'!CB120+'Detailed Avalerem Tables'!CB168+'Detailed Avalerem Tables'!CB216+'Detailed Avalerem Tables'!DD23+'Detailed Avalerem Tables'!DD72+'Detailed Avalerem Tables'!DD120+'Detailed Avalerem Tables'!DD168+'Detailed Avalerem Tables'!DD216+'Detailed Avalerem Tables'!EF23+'Detailed Avalerem Tables'!EF72+'Detailed Avalerem Tables'!EF120+'Detailed Avalerem Tables'!EF168+'Detailed Avalerem Tables'!EF216)/25 -> 12.468303 | D25: =('Detailed Avalerem Tables'!Y23+'Detailed Avalerem Tables'!Y72+'Detailed Avalerem Tables'!Y120+'Detailed Avalerem Tables'!Y168+'Detailed Avalerem Tables'!Y216+'Detailed Avalerem Tables'!BA23+'Detailed Avalerem Tables'!BA72+'Detailed Avalerem Tables'!BA120+'Detailed Avalerem Tables'!BA168+'Detailed Avalerem Tables'!BA216+'Detailed Avalerem Tables'!CC23+'Detailed Avalerem Tables'!CC72+'Detailed Avalerem Tables'!CC120+'Detailed Avalerem Tables'!CC168+'Detailed Avalerem Tables'!CC216+'Detailed Avalerem Tables'!DE23+'Detailed Avalerem Tables'!DE72+'Detailed Avalerem Tables'!DE120+'Detailed Avalerem Tables'!DE168+'Detailed Avalerem Tables'!DE216+'Detailed Avalerem Tables'!EG23+'Detailed Avalerem Tables'!EG72+'Detailed Avalerem Tables'!EG120+'Detailed Avalerem Tables'!EG168+'Detailed Avalerem Tables'!EG216)/25 -> 12.36352 | E25: =('Detailed Avalerem Tables'!Z23+'Detailed Avalerem Tables'!Z72+'Detailed Avalerem Tables'!Z120+'Detailed Avalerem Tables'!Z168+'Detailed Avalerem Tables'!Z216+'Detailed Avalerem Tables'!BB23+'Detailed Avalerem Tables'!BB72+'Detailed Avalerem Tables'!BB120+'Detailed Avalerem Tables'!BB168+'Detailed Avalerem Tables'!BB216+'Detailed Avalerem Tables'!CD23+'Detailed Avalerem Tables'!CD72+'Detailed Avalerem Tables'!CD120+'Detailed Avalerem Tables'!CD168+'Detailed Avalerem Tables'!CD216+'Detailed Avalerem Tables'!DF23+'Detailed Avalerem Tables'!DF72+'Detailed Avalerem Tables'!DF120+'Detailed Avalerem Tables'!DF168+'Detailed Avalerem Tables'!DF216+'Detailed Avalerem Tables'!EH23+'Detailed Avalerem Tables'!EH72+'Detailed Avalerem Tables'!EH120+'Detailed Avalerem Tables'!EH168+'Detailed Avalerem Tables'!EH216)/25 -> 12.487747 | F25: =('Detailed Avalerem Tables'!AA23+'Detailed Avalerem Tables'!AA72+'Detailed Avalerem Tables'!AA120+'Detailed Avalerem Tables'!AA168+'Detailed Avalerem Tables'!AA216+'Detailed Avalerem Tables'!BC23+'Detailed Avalerem Tables'!BC72+'Detailed Avalerem Tables'!BC120+'Detailed Avalerem Tables'!BC168+'Detailed Avalerem Tables'!BC216+'Detailed Avalerem Tables'!CE23+'Detailed Avalerem Tables'!CE72+'Detailed Avalerem Tables'!CE120+'Detailed Avalerem Tables'!CE168+'Detailed Avalerem Tables'!CE216+'Detailed Avalerem Tables'!DG23+'Detailed Avalerem Tables'!DG72+'Detailed Avalerem Tables'!DG120+'Detailed Avalerem Tables'!DG168+'Detailed Avalerem Tables'!DG216+'Detailed Avalerem Tables'!EI23+'Detailed Avalerem Tables'!EI72+'Detailed Avalerem Tables'!EI120+'Detailed Avalerem Tables'!EI168+'Detailed Avalerem Tables'!EI216)/25 -> 12.628678 | G25: =('Detailed Avalerem Tables'!AB23+'Detailed Avalerem Tables'!AB72+'Detailed Avalerem Tables'!AB120+'Detailed Avalerem Tables'!AB168+'Detailed Avalerem Tables'!AB216+'Detailed Avalerem Tables'!BD23+'Detailed Avalerem Tables'!BD72+'Detailed Avalerem Tables'!BD120+'Detailed Avalerem Tables'!BD168+'Detailed Avalerem Tables'!BD216+'Detailed Avalerem Tables'!CF23+'Detailed Avalerem Tables'!CF72+'Detailed Avalerem Tables'!CF120+'Detailed Avalerem Tables'!CF168+'Detailed Avalerem Tables'!CF216+'Detailed Avalerem Tables'!DH23+'Detailed Avalerem Tables'!DH72+'Detailed Avalerem Tables'!DH120+'Detailed Avalerem Tables'!DH168+'Detailed Avalerem Tables'!DH216+'Detailed Avalerem Tables'!EJ23+'Detailed Avalerem Tables'!EJ72+'Detailed Avalerem Tables'!EJ120+'Detailed Avalerem Tables'!EJ168+'Detailed Avalerem Tables'!EJ216)/25 -> 12.067767 | J25: 1 | K25: =$L$5*C25 -> 24.936605 | L25: =$L$5*D25 -> 24.727041 | M25: =$L$5*E25 -> 24.975495 | N25: =$L$5*F25 -> 25.257357 | O25: =$L$5*G25 -> 24.135535 | R25: 1 | S25: =$T$5*C25 -> 18.702454 | T25: =$T$5*D25 -> 18.545281 | U25: =$T$5*E25 -> 18.731621 | V25: =$T$5*F25 -> 18.943018 | W25: =$T$5*G25 -> 18.101651 | Z25: 1 | AA25: =$AB$5*C25 -> 14.961963 | AB25: =$AB$5*D25 -> 14.836225 | AC25: =$AB$5*E25 -> 14.985297 | AD25: =$AB$5*F25 -> 15.154414 | AE25: =$AB$5*G25 -> 14.481321 | AH25: 1 | AI25: =$AJ$5*C25 -> 12.468303 | AJ25: =$AJ$5*D25 -> 12.36352 | AK25: =$AJ$5*E25 -> 12.487747 | AL25: =$AJ$5*F25 -> 12.628678 | AM25: =$AJ$5*G25 -> 12.067767
B26: 2 | C26: =('Detailed Avalerem Tables'!X24+'Detailed Avalerem Tables'!X73+'Detailed Avalerem Tables'!X121+'Detailed Avalerem Tables'!X169+'Detailed Avalerem Tables'!X217+'Detailed Avalerem Tables'!AZ24+'Detailed Avalerem Tables'!AZ73+'Detailed Avalerem Tables'!AZ121+'Detailed Avalerem Tables'!AZ169+'Detailed Avalerem Tables'!AZ217+'Detailed Avalerem Tables'!CB24+'Detailed Avalerem Tables'!CB73+'Detailed Avalerem Tables'!CB121+'Detailed Avalerem Tables'!CB169+'Detailed Avalerem Tables'!CB217+'Detailed Avalerem Tables'!DD24+'Detailed Avalerem Tables'!DD73+'Detailed Avalerem Tables'!DD121+'Detailed Avalerem Tables'!DD169+'Detailed Avalerem Tables'!DD217+'Detailed Avalerem Tables'!EF24+'Detailed Avalerem Tables'!EF73+'Detailed Avalerem Tables'!EF121+'Detailed Avalerem Tables'!EF169+'Detailed Avalerem Tables'!EF217)/25 -> 15.430302 | D26: =('Detailed Avalerem Tables'!Y24+'Detailed Avalerem Tables'!Y73+'Detailed Avalerem Tables'!Y121+'Detailed Avalerem Tables'!Y169+'Detailed Avalerem Tables'!Y217+'Detailed Avalerem Tables'!BA24+'Detailed Avalerem Tables'!BA73+'Detailed Avalerem Tables'!BA121+'Detailed Avalerem Tables'!BA169+'Detailed Avalerem Tables'!BA217+'Detailed Avalerem Tables'!CC24+'Detailed Avalerem Tables'!CC73+'Detailed Avalerem Tables'!CC121+'Detailed Avalerem Tables'!CC169+'Detailed Avalerem Tables'!CC217+'Detailed Avalerem Tables'!DE24+'Detailed Avalerem Tables'!DE73+'Detailed Avalerem Tables'!DE121+'Detailed Avalerem Tables'!DE169+'Detailed Avalerem Tables'!DE217+'Detailed Avalerem Tables'!EG24+'Detailed Avalerem Tables'!EG73+'Detailed Avalerem Tables'!EG121+'Detailed Avalerem Tables'!EG169+'Detailed Avalerem Tables'!EG217)/25 -> 14.768225 | E26: =('Detailed Avalerem Tables'!Z24+'Detailed Avalerem Tables'!Z73+'Detailed Avalerem Tables'!Z121+'Detailed Avalerem Tables'!Z169+'Detailed Avalerem Tables'!Z217+'Detailed Avalerem Tables'!BB24+'Detailed Avalerem Tables'!BB73+'Detailed Avalerem Tables'!BB121+'Detailed Avalerem Tables'!BB169+'Detailed Avalerem Tables'!BB217+'Detailed Avalerem Tables'!CD24+'Detailed Avalerem Tables'!CD73+'Detailed Avalerem Tables'!CD121+'Detailed Avalerem Tables'!CD169+'Detailed Avalerem Tables'!CD217+'Detailed Avalerem Tables'!DF24+'Detailed Avalerem Tables'!DF73+'Detailed Avalerem Tables'!DF121+'Detailed Avalerem Tables'!DF169+'Detailed Avalerem Tables'!DF217+'Detailed Avalerem Tables'!EH24+'Detailed Avalerem Tables'!EH73+'Detailed Avalerem Tables'!EH121+'Detailed Avalerem Tables'!EH169+'Detailed Avalerem Tables'!EH217)/25 -> 15.349914 | F26: =('Detailed Avalerem Tables'!AA24+'Detailed Avalerem Tables'!AA73+'Detailed Avalerem Tables'!AA121+'Detailed Avalerem Tables'!AA169+'Detailed Avalerem Tables'!AA217+'Detailed Avalerem Tables'!BC24+'Detailed Avalerem Tables'!BC73+'Detailed Avalerem Tables'!BC121+'Detailed Avalerem Tables'!BC169+'Detailed Avalerem Tables'!BC217+'Detailed Avalerem Tables'!CE24+'Detailed Avalerem Tables'!CE73+'Detailed Avalerem Tables'!CE121+'Detailed Avalerem Tables'!CE169+'Detailed Avalerem Tables'!CE217+'Detailed Avalerem Tables'!DG24+'Detailed Avalerem Tables'!DG73+'Detailed Avalerem Tables'!DG121+'Detailed Avalerem Tables'!DG169+'Detailed Avalerem Tables'!DG217+'Detailed Avalerem Tables'!EI24+'Detailed Avalerem Tables'!EI73+'Detailed Avalerem Tables'!EI121+'Detailed Avalerem Tables'!EI169+'Detailed Avalerem Tables'!EI217)/25 -> 14.818997 | G26: =('Detailed Avalerem Tables'!AB24+'Detailed Avalerem Tables'!AB73+'Detailed Avalerem Tables'!AB121+'Detailed Avalerem Tables'!AB169+'Detailed Avalerem Tables'!AB217+'Detailed Avalerem Tables'!BD24+'Detailed Avalerem Tables'!BD73+'Detailed Avalerem Tables'!BD121+'Detailed Avalerem Tables'!BD169+'Detailed Avalerem Tables'!BD217+'Detailed Avalerem Tables'!CF24+'Detailed Avalerem Tables'!CF73+'Detailed Avalerem Tables'!CF121+'Detailed Avalerem Tables'!CF169+'Detailed Avalerem Tables'!CF217+'Detailed Avalerem Tables'!DH24+'Detailed Avalerem Tables'!DH73+'Detailed Avalerem Tables'!DH121+'Detailed Avalerem Tables'!DH169+'Detailed Avalerem Tables'!DH217+'Detailed Avalerem Tables'!EJ24+'Detailed Avalerem Tables'!EJ73+'Detailed Avalerem Tables'!EJ121+'Detailed Avalerem Tables'!EJ169+'Detailed Avalerem Tables'!EJ217)/25 -> 14.635038 | J26: 2 | K26: =$L$5*C26 -> 30.860605 | L26: =$L$5*D26 -> 29.536451 | M26: =$L$5*E26 -> 30.699827 | N26: =$L$5*F26 -> 29.637994 | O26: =$L$5*G26 -> 29.270077 | R26: 2 | S26: =$T$5*C26 -> 23.145454 | T26: =$T$5*D26 -> 22.152338 | U26: =$T$5*E26 -> 23.024871 | V26: =$T$5*F26 -> 22.228496 | W26: =$T$5*G26 -> 21.952558 | Z26: 2 | AA26: =$AB$5*C26 -> 18.516363 | AB26: =$AB$5*D26 -> 17.72187 | AC26: =$AB$5*E26 -> 18.419896 | AD26: =$AB$5*F26 -> 17.782797 | AE26: =$AB$5*G26 -> 17.562046 | AH26: 2 | AI26: =$AJ$5*C26 -> 15.430302 | AJ26: =$AJ$5*D26 -> 14.768225 | AK26: =$AJ$5*E26 -> 15.349914 | AL26: =$AJ$5*F26 -> 14.818997 | AM26: =$AJ$5*G26 -> 14.635038
B27: 3 | C27: =('Detailed Avalerem Tables'!X25+'Detailed Avalerem Tables'!X74+'Detailed Avalerem Tables'!X122+'Detailed Avalerem Tables'!X170+'Detailed Avalerem Tables'!X218+'Detailed Avalerem Tables'!AZ25+'Detailed Avalerem Tables'!AZ74+'Detailed Avalerem Tables'!AZ122+'Detailed Avalerem Tables'!AZ170+'Detailed Avalerem Tables'!AZ218+'Detailed Avalerem Tables'!CB25+'Detailed Avalerem Tables'!CB74+'Detailed Avalerem Tables'!CB122+'Detailed Avalerem Tables'!CB170+'Detailed Avalerem Tables'!CB218+'Detailed Avalerem Tables'!DD25+'Detailed Avalerem Tables'!DD74+'Detailed Avalerem Tables'!DD122+'Detailed Avalerem Tables'!DD170+'Detailed Avalerem Tables'!DD218+'Detailed Avalerem Tables'!EF25+'Detailed Avalerem Tables'!EF74+'Detailed Avalerem Tables'!EF122+'Detailed Avalerem Tables'!EF170+'Detailed Avalerem Tables'!EF218)/25 -> 15.474168 | D27: =('Detailed Avalerem Tables'!Y25+'Detailed Avalerem Tables'!Y74+'Detailed Avalerem Tables'!Y122+'Detailed Avalerem Tables'!Y170+'Detailed Avalerem Tables'!Y218+'Detailed Avalerem Tables'!BA25+'Detailed Avalerem Tables'!BA74+'Detailed Avalerem Tables'!BA122+'Detailed Avalerem Tables'!BA170+'Detailed Avalerem Tables'!BA218+'Detailed Avalerem Tables'!CC25+'Detailed Avalerem Tables'!CC74+'Detailed Avalerem Tables'!CC122+'Detailed Avalerem Tables'!CC170+'Detailed Avalerem Tables'!CC218+'Detailed Avalerem Tables'!DE25+'Detailed Avalerem Tables'!DE74+'Detailed Avalerem Tables'!DE122+'Detailed Avalerem Tables'!DE170+'Detailed Avalerem Tables'!DE218+'Detailed Avalerem Tables'!EG25+'Detailed Avalerem Tables'!EG74+'Detailed Avalerem Tables'!EG122+'Detailed Avalerem Tables'!EG170+'Detailed Avalerem Tables'!EG218)/25 -> 15.550808 | E27: =('Detailed Avalerem Tables'!Z25+'Detailed Avalerem Tables'!Z74+'Detailed Avalerem Tables'!Z122+'Detailed Avalerem Tables'!Z170+'Detailed Avalerem Tables'!Z218+'Detailed Avalerem Tables'!BB25+'Detailed Avalerem Tables'!BB74+'Detailed Avalerem Tables'!BB122+'Detailed Avalerem Tables'!BB170+'Detailed Avalerem Tables'!BB218+'Detailed Avalerem Tables'!CD25+'Detailed Avalerem Tables'!CD74+'Detailed Avalerem Tables'!CD122+'Detailed Avalerem Tables'!CD170+'Detailed Avalerem Tables'!CD218+'Detailed Avalerem Tables'!DF25+'Detailed Avalerem Tables'!DF74+'Detailed Avalerem Tables'!DF122+'Detailed Avalerem Tables'!DF170+'Detailed Avalerem Tables'!DF218+'Detailed Avalerem Tables'!EH25+'Detailed Avalerem Tables'!EH74+'Detailed Avalerem Tables'!EH122+'Detailed Avalerem Tables'!EH170+'Detailed Avalerem Tables'!EH218)/25 -> 15.473964 | F27: =('Detailed Avalerem Tables'!AA25+'Detailed Avalerem Tables'!AA74+'Detailed Avalerem Tables'!AA122+'Detailed Avalerem Tables'!AA170+'Detailed Avalerem Tables'!AA218+'Detailed Avalerem Tables'!BC25+'Detailed Avalerem Tables'!BC74+'Detailed Avalerem Tables'!BC122+'Detailed Avalerem Tables'!BC170+'Detailed Avalerem Tables'!BC218+'Detailed Avalerem Tables'!CE25+'Detailed Avalerem Tables'!CE74+'Detailed Avalerem Tables'!CE122+'Detailed Avalerem Tables'!CE170+'Detailed Avalerem Tables'!CE218+'Detailed Avalerem Tables'!DG25+'Detailed Avalerem Tables'!DG74+'Detailed Avalerem Tables'!DG122+'Detailed Avalerem Tables'!DG170+'Detailed Avalerem Tables'!DG218+'Detailed Avalerem Tables'!EI25+'Detailed Avalerem Tables'!EI74+'Detailed Avalerem Tables'!EI122+'Detailed Avalerem Tables'!EI170+'Detailed Avalerem Tables'!EI218)/25 -> 15.176509 | G27: =('Detailed Avalerem Tables'!AB25+'Detailed Avalerem Tables'!AB74+'Detailed Avalerem Tables'!AB122+'Detailed Avalerem Tables'!AB170+'Detailed Avalerem Tables'!AB218+'Detailed Avalerem Tables'!BD25+'Detailed Avalerem Tables'!BD74+'Detailed Avalerem Tables'!BD122+'Detailed Avalerem Tables'!BD170+'Detailed Avalerem Tables'!BD218+'Detailed Avalerem Tables'!CF25+'Detailed Avalerem Tables'!CF74+'Detailed Avalerem Tables'!CF122+'Detailed Avalerem Tables'!CF170+'Detailed Avalerem Tables'!CF218+'Detailed Avalerem Tables'!DH25+'Detailed Avalerem Tables'!DH74+'Detailed Avalerem Tables'!DH122+'Detailed Avalerem Tables'!DH170+'Detailed Avalerem Tables'!DH218+'Detailed Avalerem Tables'!EJ25+'Detailed Avalerem Tables'!EJ74+'Detailed Avalerem Tables'!EJ122+'Detailed Avalerem Tables'!EJ170+'Detailed Avalerem Tables'!EJ218)/25 -> 14.739004 | J27: 3 | K27: =$L$5*C27 -> 30.948336 | L27: =$L$5*D27 -> 31.101617 | M27: =$L$5*E27 -> 30.947927 | N27: =$L$5*F27 -> 30.353018 | O27: =$L$5*G27 -> 29.478009 | R27: 3 | S27: =$T$5*C27 -> 23.211252 | T27: =$T$5*D27 -> 23.326213 | U27: =$T$5*E27 -> 23.210946 | V27: =$T$5*F27 -> 22.764764 | W27: =$T$5*G27 -> 22.108506 | Z27: 3 | AA27: =$AB$5*C27 -> 18.569001 | AB27: =$AB$5*D27 -> 18.66097 | AC27: =$AB$5*E27 -> 18.568756 | AD27: =$AB$5*F27 -> 18.211811 | AE27: =$AB$5*G27 -> 17.686805 | AH27: 3 | AI27: =$AJ$5*C27 -> 15.474168 | AJ27: =$AJ$5*D27 -> 15.550808 | AK27: =$AJ$5*E27 -> 15.473964 | AL27: =$AJ$5*F27 -> 15.176509 | AM27: =$AJ$5*G27 -> 14.739004
B28: 4 | C28: =('Detailed Avalerem Tables'!X26+'Detailed Avalerem Tables'!X75+'Detailed Avalerem Tables'!X123+'Detailed Avalerem Tables'!X171+'Detailed Avalerem Tables'!X219+'Detailed Avalerem Tables'!AZ26+'Detailed Avalerem Tables'!AZ75+'Detailed Avalerem Tables'!AZ123+'Detailed Avalerem Tables'!AZ171+'Detailed Avalerem Tables'!AZ219+'Detailed Avalerem Tables'!CB26+'Detailed Avalerem Tables'!CB75+'Detailed Avalerem Tables'!CB123+'Detailed Avalerem Tables'!CB171+'Detailed Avalerem Tables'!CB219+'Detailed Avalerem Tables'!DD26+'Detailed Avalerem Tables'!DD75+'Detailed Avalerem Tables'!DD123+'Detailed Avalerem Tables'!DD171+'Detailed Avalerem Tables'!DD219+'Detailed Avalerem Tables'!EF26+'Detailed Avalerem Tables'!EF75+'Detailed Avalerem Tables'!EF123+'Detailed Avalerem Tables'!EF171+'Detailed Avalerem Tables'!EF219)/25 -> 16.710066 | D28: =('Detailed Avalerem Tables'!Y26+'Detailed Avalerem Tables'!Y75+'Detailed Avalerem Tables'!Y123+'Detailed Avalerem Tables'!Y171+'Detailed Avalerem Tables'!Y219+'Detailed Avalerem Tables'!BA26+'Detailed Avalerem Tables'!BA75+'Detailed Avalerem Tables'!BA123+'Detailed Avalerem Tables'!BA171+'Detailed Avalerem Tables'!BA219+'Detailed Avalerem Tables'!CC26+'Detailed Avalerem Tables'!CC75+'Detailed Avalerem Tables'!CC123+'Detailed Avalerem Tables'!CC171+'Detailed Avalerem Tables'!CC219+'Detailed Avalerem Tables'!DE26+'Detailed Avalerem Tables'!DE75+'Detailed Avalerem Tables'!DE123+'Detailed Avalerem Tables'!DE171+'Detailed Avalerem Tables'!DE219+'Detailed Avalerem Tables'!EG26+'Detailed Avalerem Tables'!EG75+'Detailed Avalerem Tables'!EG123+'Detailed Avalerem Tables'!EG171+'Detailed Avalerem Tables'!EG219)/25 -> 15.839904 | E28: =('Detailed Avalerem Tables'!Z26+'Detailed Avalerem Tables'!Z75+'Detailed Avalerem Tables'!Z123+'Detailed Avalerem Tables'!Z171+'Detailed Avalerem Tables'!Z219+'Detailed Avalerem Tables'!BB26+'Detailed Avalerem Tables'!BB75+'Detailed Avalerem Tables'!BB123+'Detailed Avalerem Tables'!BB171+'Detailed Avalerem Tables'!BB219+'Detailed Avalerem Tables'!CD26+'Detailed Avalerem Tables'!CD75+'Detailed Avalerem Tables'!CD123+'Detailed Avalerem Tables'!CD171+'Detailed Avalerem Tables'!CD219+'Detailed Avalerem Tables'!DF26+'Detailed Avalerem Tables'!DF75+'Detailed Avalerem Tables'!DF123+'Detailed Avalerem Tables'!DF171+'Detailed Avalerem Tables'!DF219+'Detailed Avalerem Tables'!EH26+'Detailed Avalerem Tables'!EH75+'Detailed Avalerem Tables'!EH123+'Detailed Avalerem Tables'!EH171+'Detailed Avalerem Tables'!EH219)/25 -> 15.91818 | F28: =('Detailed Avalerem Tables'!AA26+'Detailed Avalerem Tables'!AA75+'Detailed Avalerem Tables'!AA123+'Detailed Avalerem Tables'!AA171+'Detailed Avalerem Tables'!AA219+'Detailed Avalerem Tables'!BC26+'Detailed Avalerem Tables'!BC75+'Detailed Avalerem Tables'!BC123+'Detailed Avalerem Tables'!BC171+'Detailed Avalerem Tables'!BC219+'Detailed Avalerem Tables'!CE26+'Detailed Avalerem Tables'!CE75+'Detailed Avalerem Tables'!CE123+'Detailed Avalerem Tables'!CE171+'Detailed Avalerem Tables'!CE219+'Detailed Avalerem Tables'!DG26+'Detailed Avalerem Tables'!DG75+'Detailed Avalerem Tables'!DG123+'Detailed Avalerem Tables'!DG171+'Detailed Avalerem Tables'!DG219+'Detailed Avalerem Tables'!EI26+'Detailed Avalerem Tables'!EI75+'Detailed Avalerem Tables'!EI123+'Detailed Avalerem Tables'!EI171+'Detailed Avalerem Tables'!EI219)/25 -> 15.272685 | G28: =('Detailed Avalerem Tables'!AB26+'Detailed Avalerem Tables'!AB75+'Detailed Avalerem Tables'!AB123+'Detailed Avalerem Tables'!AB171+'Detailed Avalerem Tables'!AB219+'Detailed Avalerem Tables'!BD26+'Detailed Avalerem Tables'!BD75+'Detailed Avalerem Tables'!BD123+'Detailed Avalerem Tables'!BD171+'Detailed Avalerem Tables'!BD219+'Detailed Avalerem Tables'!CF26+'Detailed Avalerem Tables'!CF75+'Detailed Avalerem Tables'!CF123+'Detailed Avalerem Tables'!CF171+'Detailed Avalerem Tables'!CF219+'Detailed Avalerem Tables'!DH26+'Detailed Avalerem Tables'!DH75+'Detailed Avalerem Tables'!DH123+'Detailed Avalerem Tables'!DH171+'Detailed Avalerem Tables'!DH219+'Detailed Avalerem Tables'!EJ26+'Detailed Avalerem Tables'!EJ75+'Detailed Avalerem Tables'!EJ123+'Detailed Avalerem Tables'!EJ171+'Detailed Avalerem Tables'!EJ219)/25 -> 15.41248 | J28: 4 | K28: =$L$5*C28 -> 33.420133 | L28: =$L$5*D28 -> 31.679807 | M28: =$L$5*E28 -> 31.836359 | N28: =$L$5*F28 -> 30.545369 | O28: =$L$5*G28 -> 30.82496 | R28: 4 | S28: =$T$5*C28 -> 25.0651 | T28: =$T$5*D28 -> 23.759856 | U28: =$T$5*E28 -> 23.877269 | V28: =$T$5*F28 -> 22.909027 | W28: =$T$5*G28 -> 23.11872 | Z28: 4 | AA28: =$AB$5*C28 -> 20.05208 | AB28: =$AB$5*D28 -> 19.007884 | AC28: =$AB$5*E28 -> 19.101815 | AD28: =$AB$5*F28 -> 18.327222 | AE28: =$AB$5*G28 -> 18.494976 | AH28: 4 | AI28: =$AJ$5*C28 -> 16.710066 | AJ28: =$AJ$5*D28 -> 15.839904 | AK28: =$AJ$5*E28 -> 15.91818 | AL28: =$AJ$5*F28 -> 15.272685 | AM28: =$AJ$5*G28 -> 15.41248
B29: 5 | C29: =('Detailed Avalerem Tables'!X27+'Detailed Avalerem Tables'!X76+'Detailed Avalerem Tables'!X124+'Detailed Avalerem Tables'!X172+'Detailed Avalerem Tables'!X220+'Detailed Avalerem Tables'!AZ27+'Detailed Avalerem Tables'!AZ76+'Detailed Avalerem Tables'!AZ124+'Detailed Avalerem Tables'!AZ172+'Detailed Avalerem Tables'!AZ220+'Detailed Avalerem Tables'!CB27+'Detailed Avalerem Tables'!CB76+'Detailed Avalerem Tables'!CB124+'Detailed Avalerem Tables'!CB172+'Detailed Avalerem Tables'!CB220+'Detailed Avalerem Tables'!DD27+'Detailed Avalerem Tables'!DD76+'Detailed Avalerem Tables'!DD124+'Detailed Avalerem Tables'!DD172+'Detailed Avalerem Tables'!DD220+'Detailed Avalerem Tables'!EF27+'Detailed Avalerem Tables'!EF76+'Detailed Avalerem Tables'!EF124+'Detailed Avalerem Tables'!EF172+'Detailed Avalerem Tables'!EF220)/25 -> 13.748067 | D29: =('Detailed Avalerem Tables'!Y27+'Detailed Avalerem Tables'!Y76+'Detailed Avalerem Tables'!Y124+'Detailed Avalerem Tables'!Y172+'Detailed Avalerem Tables'!Y220+'Detailed Avalerem Tables'!BA27+'Detailed Avalerem Tables'!BA76+'Detailed Avalerem Tables'!BA124+'Detailed Avalerem Tables'!BA172+'Detailed Avalerem Tables'!BA220+'Detailed Avalerem Tables'!CC27+'Detailed Avalerem Tables'!CC76+'Detailed Avalerem Tables'!CC124+'Detailed Avalerem Tables'!CC172+'Detailed Avalerem Tables'!CC220+'Detailed Avalerem Tables'!DE27+'Detailed Avalerem Tables'!DE76+'Detailed Avalerem Tables'!DE124+'Detailed Avalerem Tables'!DE172+'Detailed Avalerem Tables'!DE220+'Detailed Avalerem Tables'!EG27+'Detailed Avalerem Tables'!EG76+'Detailed Avalerem Tables'!EG124+'Detailed Avalerem Tables'!EG172+'Detailed Avalerem Tables'!EG220)/25 -> 13.435199 | E29: =('Detailed Avalerem Tables'!Z27+'Detailed Avalerem Tables'!Z76+'Detailed Avalerem Tables'!Z124+'Detailed Avalerem Tables'!Z172+'Detailed Avalerem Tables'!Z220+'Detailed Avalerem Tables'!BB27+'Detailed Avalerem Tables'!BB76+'Detailed Avalerem Tables'!BB124+'Detailed Avalerem Tables'!BB172+'Detailed Avalerem Tables'!BB220+'Detailed Avalerem Tables'!CD27+'Detailed Avalerem Tables'!CD76+'Detailed Avalerem Tables'!CD124+'Detailed Avalerem Tables'!CD172+'Detailed Avalerem Tables'!CD220+'Detailed Avalerem Tables'!DF27+'Detailed Avalerem Tables'!DF76+'Detailed Avalerem Tables'!DF124+'Detailed Avalerem Tables'!DF172+'Detailed Avalerem Tables'!DF220+'Detailed Avalerem Tables'!EH27+'Detailed Avalerem Tables'!EH76+'Detailed Avalerem Tables'!EH124+'Detailed Avalerem Tables'!EH172+'Detailed Avalerem Tables'!EH220)/25 -> 13.056013 | F29: =('Detailed Avalerem Tables'!AA27+'Detailed Avalerem Tables'!AA76+'Detailed Avalerem Tables'!AA124+'Detailed Avalerem Tables'!AA172+'Detailed Avalerem Tables'!AA220+'Detailed Avalerem Tables'!BC27+'Detailed Avalerem Tables'!BC76+'Detailed Avalerem Tables'!BC124+'Detailed Avalerem Tables'!BC172+'Detailed Avalerem Tables'!BC220+'Detailed Avalerem Tables'!CE27+'Detailed Avalerem Tables'!CE76+'Detailed Avalerem Tables'!CE124+'Detailed Avalerem Tables'!CE172+'Detailed Avalerem Tables'!CE220+'Detailed Avalerem Tables'!DG27+'Detailed Avalerem Tables'!DG76+'Detailed Avalerem Tables'!DG124+'Detailed Avalerem Tables'!DG172+'Detailed Avalerem Tables'!DG220+'Detailed Avalerem Tables'!EI27+'Detailed Avalerem Tables'!EI76+'Detailed Avalerem Tables'!EI124+'Detailed Avalerem Tables'!EI172+'Detailed Avalerem Tables'!EI220)/25 -> 13.082366 | G29: =('Detailed Avalerem Tables'!AB27+'Detailed Avalerem Tables'!AB76+'Detailed Avalerem Tables'!AB124+'Detailed Avalerem Tables'!AB172+'Detailed Avalerem Tables'!AB220+'Detailed Avalerem Tables'!BD27+'Detailed Avalerem Tables'!BD76+'Detailed Avalerem Tables'!BD124+'Detailed Avalerem Tables'!BD172+'Detailed Avalerem Tables'!BD220+'Detailed Avalerem Tables'!CF27+'Detailed Avalerem Tables'!CF76+'Detailed Avalerem Tables'!CF124+'Detailed Avalerem Tables'!CF172+'Detailed Avalerem Tables'!CF220+'Detailed Avalerem Tables'!DH27+'Detailed Avalerem Tables'!DH76+'Detailed Avalerem Tables'!DH124+'Detailed Avalerem Tables'!DH172+'Detailed Avalerem Tables'!DH220+'Detailed Avalerem Tables'!EJ27+'Detailed Avalerem Tables'!EJ76+'Detailed Avalerem Tables'!EJ124+'Detailed Avalerem Tables'!EJ172+'Detailed Avalerem Tables'!EJ220)/25 -> 12.845209 | J29: 5 | K29: =$L$5*C29 -> 27.496133 | L29: =$L$5*D29 -> 26.870398 | M29: =$L$5*E29 -> 26.112026 | N29: =$L$5*F29 -> 26.164732 | O29: =$L$5*G29 -> 25.690418 | R29: 5 | S29: =$T$5*C29 -> 20.6221 | T29: =$T$5*D29 -> 20.152798 | U29: =$T$5*E29 -> 19.58402 | V29: =$T$5*F29 -> 19.623549 | W29: =$T$5*G29 -> 19.267813 | Z29: 5 | AA29: =$AB$5*C29 -> 16.49768 | AB29: =$AB$5*D29 -> 16.122239 | AC29: =$AB$5*E29 -> 15.667216 | AD29: =$AB$5*F29 -> 15.698839 | AE29: =$AB$5*G29 -> 15.414251 | AH29: 5 | AI29: =$AJ$5*C29 -> 13.748067 | AJ29: =$AJ$5*D29 -> 13.435199 | AK29: =$AJ$5*E29 -> 13.056013 | AL29: =$AJ$5*F29 -> 13.082366 | AM29: =$AJ$5*G29 -> 12.845209
